Workbook

Sheet 📋 Start Here
B2: PERSONAL LIFE OS Free Template — AnalyticsByShanikwa
B7: Built from real work. Not theory. — analyticsbyshanikwa.com
B9: A NOTE FROM NIKKI
B10: Hey — welcome, and thank you for downloading this. I built this template because I kept running into a problem most productivity content doesn't address: what do you do when you're organized at work but your personal life has no system? At work you have project management tools, meeting notes, dashboards. At home you have sticky notes, a notes app, and a mental list that's always slightly on fire. This is my answer to that gap. Five tabs. Each one covers a different dimension of your personal life that deserves a system but usually doesn't have one. — Nikki analyticsbyshanikwa.com
B20: THE ONE THING — READ THIS FIRST
B21: Start with the Weekly Life Planner (Tab 2). Fill in your Top 3 Priorities for this week before you touch anything else. That takes 5 minutes and activates the whole system. The other four tabs are more useful once you have at least one week of the planner filled in.
B26: THE 5 TABS — WHAT EACH ONE DOES
B27: 📋 Start Here | C27: You're here. Read this once, then come back whenever you need a reset.
B28: 📅 Weekly Life Planner | C28: Your weekly command center. Top priorities, daily schedule blocks, habit tracker, energy log. Fill in Sunday evening or Monday morning.
B29: 💰 Monthly Money Snapshot | C29: Income, fixed expenses, variable spending, savings targets. One-page personal P&L. Update it on the 1st of each month.
B30: 🎯 Goals Dashboard | C30: 3 active goals with 90-day timelines, weekly action steps, and progress bars. Review weekly. Update monthly.
B31: 🙏 Daily Wins & Gratitude | C31: End-of-day 3-minute log. Three wins, three gratitudes, one lesson, mood rating. 30 days of entries pre-formatted.
B33: HOW TO USE THIS IN GOOGLE SHEETS
B34: Step 1 | C34: Open the file in Google Drive and click File → Make a copy — takes 30 seconds.
B35: Step 2 | C35: Rename your copy something memorable: 'Nikki's Life OS — 2026' works.
B36: Step 3 | C36: Bookmark it or pin it in Google Sheets. If it's hard to find, you won't use it.
B37: Step 4 | C37: Open Tab 2 (Weekly Life Planner) and fill in your Top 3 Priorities for this week.
B38: Step 5 | C38: Set a Sunday evening recurring calendar reminder: '10 min — update life OS.'
B40: Questions? Email hello@analyticsbyshanikwa.com · More templates at analyticsbyshanikwa.com

Sheet 📅 Weekly Life Planner
B2: WEEKLY LIFE PLANNER
B4: WEEK OF: | F4: WEEK THEME / FOCUS:
B6: TOP 3 PRIORITIES THIS WEEK
B7: #1
B8: #2
B9: #3
B11: DAILY SCHEDULE — KEY BLOCKS (fill in your top 1–2 focus areas per day)
B12: TIME BLOCK | C12: MON | D12: TUE | E12: WED | F12: THU | G12: FRI | H12: SAT | I12: SUN
B13: MORNING 5am–9am
B14: MID-MORNING 9am–12pm
B15: AFTERNOON 12pm–3pm
B16: LATE AFTERNOON 3pm–6pm
B17: EVENING 6pm–9pm
B19: HABIT TRACKER — mark ✓ when done
B20: HABIT | C20: MON | D20: TUE | E20: WED | F20: THU | G20: FRI | H20: SAT | I20: SUN
B21: Morning prayer / devotional
B22: Move my body (30+ min)
B23: Read (non-screen, 20+ min)
B24: No scrolling after 9pm
B25: Log spending
B26: [Your habit here]
B27: [Your habit here]
B29: HABITS COMPLETED | C29: =COUNTIF(C21:C27,"✓") -> 0 | D29: =COUNTIF(D21:D27,"✓") -> 0 | E29: =COUNTIF(E21:E27,"✓") -> 0 | F29: =COUNTIF(F21:F27,"✓") -> 0 | G29: =COUNTIF(G21:G27,"✓") -> 0 | H29: =COUNTIF(H21:H27,"✓") -> 0 | I29: =COUNTIF(I21:I27,"✓") -> 0
B31: ENERGY LOG — rate each day 1–5 (1=depleted, 5=peak)
B32: MORNING energy
B33: AFTERNOON energy
B34: EVENING energy
B35: OVERALL day score | C35: =IFERROR(AVERAGE(C32:C34),"") | D35: =IFERROR(AVERAGE(D32:D34),"") | E35: =IFERROR(AVERAGE(E32:E34),"") | F35: =IFERROR(AVERAGE(F32:F34),"") | G35: =IFERROR(AVERAGE(G32:G34),"") | H35: =IFERROR(AVERAGE(H32:H34),"") | I35: =IFERROR(AVERAGE(I32:I34),"")
B37: WEEKLY REFLECTION (fill in Friday or Sunday)
B38: What went well this week?
B40: What didn't work — and why?
B42: What do I want to do differently next week?
B44: One thing I'm proud of:

Sheet 💰 Monthly Money Snapshot
B2: MONTHLY MONEY SNAPSHOT
B4: MONTH / YEAR:
B6: INCOME
B7: SOURCE | C7: BUDGETED | D7: ACTUAL | E7: DIFFERENCE
B8: Primary salary / pay | C8: 0 | D8: 0 | E8: =D8-C8 -> 0
B9: Side income / freelance | C9: 0 | D9: 0 | E9: =D9-C9 -> 0
B10: Digital product sales | C10: 0 | D10: 0 | E10: =D10-C10 -> 0
B11: Other income | C11: 0 | D11: 0 | E11: =D11-C11 -> 0
B12: Other income | C12: 0 | D12: 0 | E12: =D12-C12 -> 0
B13: TOTAL INCOME | C13: =SUM(C8:C12) -> 0 | D13: =SUM(D8:D12) -> 0 | E13: =SUM(E8:E12) -> 0
B15: FIXED EXPENSES (same every month)
B16: EXPENSE | C16: BUDGETED | D16: ACTUAL | E16: DIFFERENCE
B17: Rent / mortgage | C17: 0 | D17: 0 | E17: =D17-C17 -> 0
B18: Car payment | C18: 0 | D18: 0 | E18: =D18-C18 -> 0
B19: Insurance (health/car/life) | C19: 0 | D19: 0 | E19: =D19-C19 -> 0
B20: Subscriptions (list all) | C20: 0 | D20: 0 | E20: =D20-C20 -> 0
B21: Loan payments | C21: 0 | D21: 0 | E21: =D21-C21 -> 0
B22: Other fixed | C22: 0 | D22: 0 | E22: =D22-C22 -> 0
B23: Other fixed | C23: 0 | D23: 0 | E23: =D23-C23 -> 0
B24: TOTAL FIXED EXPENSES | C24: =SUM(C17:C23) -> 0 | D24: =SUM(D17:D23) -> 0 | E24: =SUM(E17:E23) -> 0
B26: VARIABLE EXPENSES (changes month to month)
B27: EXPENSE | C27: BUDGETED | D27: ACTUAL | E27: DIFFERENCE
B28: Groceries | C28: 0 | D28: 0 | E28: =D28-C28 -> 0
B29: Gas / transportation | C29: 0 | D29: 0 | E29: =D29-C29 -> 0
B30: Dining out | C30: 0 | D30: 0 | E30: =D30-C30 -> 0
B31: Entertainment | C31: 0 | D31: 0 | E31: =D31-C31 -> 0
B32: Clothing / shopping | C32: 0 | D32: 0 | E32: =D32-C32 -> 0
B33: Personal care | C33: 0 | D33: 0 | E33: =D33-C33 -> 0
B34: Giving / charitable | C34: 0 | D34: 0 | E34: =D34-C34 -> 0
B35: Miscellaneous | C35: 0 | D35: 0 | E35: =D35-C35 -> 0
B36: TOTAL VARIABLE EXPENSES | C36: =SUM(C28:C35) -> 0 | D36: =SUM(D28:D35) -> 0 | E36: =SUM(E28:E35) -> 0
B38: SAVINGS TARGETS & MONTHLY SUMMARY
B39: Emergency fund contribution | C39: 0 | D39: 0 | E39: =D39-C39 -> 0
B40: Retirement / investment contribution | C40: 0 | D40: 0 | E40: =D40-C40 -> 0
B41: Short-term savings (travel, big purchase) | C41: 0 | D41: 0 | E41: =D41-C41 -> 0
B42: Sinking funds (irregular bills) | C42: 0 | D42: 0 | E42: =D42-C42 -> 0
B43: TOTAL SAVINGS | C43: =SUM(C39:C42) -> 0 | D43: =SUM(D39:D42) -> 0 | E43: =SUM(E39:E42) -> 0
B44: TOTAL INCOME (Budget) | C44: =C13 -> 0
B45: TOTAL INCOME (Actual) | C45: =D13 -> 0
B46: TOTAL EXPENSES (Budget) | C46: =C24+C36+C42 -> 0
...

Sheet 🎯 Goals Dashboard
B2: GOALS DASHBOARD — 90-DAY TRACKER
B4: TIP: Review this tab every Sunday. Update progress %. When a goal hits 100%, mark it DONE and set a new one.
B6: GOAL 1
B7: GOAL: | C7: e.g., Land first data analyst role by end of quarter
B8: START DATE: | D8: TARGET DATE: | F8: % COMPLETE: | G8: 0%
B9: WHY THIS GOAL MATTERS:
B11: WEEK | C11: ACTION STEP | E11: DUE DATE | F11: DONE? | G11: NOTES
B12: Week 1
B13: Week 2
B14: Week 3
B15: Week 4
B16: Week 5
B17: Week 6
B18: MONTHLY REVIEW NOTES:
B21: GOAL 2
B22: GOAL: | C22: e.g., Complete FAR section with 85%+ MCQ average
B23: START DATE: | D23: TARGET DATE: | F23: % COMPLETE: | G23: 0%
B24: WHY THIS GOAL MATTERS:
B26: WEEK | C26: ACTION STEP | E26: DUE DATE | F26: DONE? | G26: NOTES
B27: Week 1
B28: Week 2
B29: Week 3
B30: Week 4
B31: Week 5
B32: Week 6
B33: MONTHLY REVIEW NOTES:
B36: GOAL 3
B37: GOAL: | C37: e.g., Pay off $4,200 credit card by month 3
B38: START DATE: | D38: TARGET DATE: | F38: % COMPLETE: | G38: 0%
B39: WHY THIS GOAL MATTERS:
B41: WEEK | C41: ACTION STEP | E41: DUE DATE | F41: DONE? | G41: NOTES
B42: Week 1
B43: Week 2
B44: Week 3
B45: Week 4
B46: Week 5
B47: Week 6
B48: MONTHLY REVIEW NOTES:

Sheet 🙏 Daily Wins & Gratitude
B2: DAILY WINS & GRATITUDE — 30-Day Log
B4: 3 minutes at the end of each day. The goal is not positivity — it is pattern recognition. What keeps showing up as a win? What keeps costing you energy?
B6: DATE | C6: 3 WINS (one sentence each) | D6: 3 GRATITUDES | E6: ONE LESSON / INSIGHT | F6: MOOD 1–5
B7: Day 1
B8: Day 2
B9: Day 3
B10: Day 4
B11: Day 5
B12: Day 6
B13: Day 7
B14: Day 8
B15: Day 9
B16: Day 10
B17: Day 11
B18: Day 12
... B36: Day 30
B38: AVERAGE MOOD — 30 DAYS | F38: =IFERROR(AVERAGE(F7:F36),"")
B40: 30-DAY REFLECTION — What pattern showed up?
B41: What type of win showed up most often?
B43: What are you consistently grateful for?
B45: What lessons kept repeating?
B47: What would you do differently in the next 30 days?
B51: 📊 30-DAY REFLECTION STATS
B52: AVG MOOD (1–5) | C52: DAYS LOGGED | D52: HIGH MOOD DAYS (≥4) | E52: LOW MOOD DAYS (≤2) | F52: WINS LOGGED
B53: =IFERROR(AVERAGEIF(F4:F33,">0"),0) -> 0 | C53: =COUNTA(B4:B33) -> 29 | D53: =COUNTIF(F4:F33,">=4") -> 0 | E53: =COUNTIF(F4:F33,"<=2") -> 0 | F53: =COUNTA(C4:C33) -> 1

Sheet 💸 Debt Tracker
B1: 💸 DEBT TRACKER — SNOWBALL & AVALANCHE
B2: Built from real work. Not theory. — analyticsbyshanikwa.com
B3: 📌 Enter debts in rows 9–18. SNOWBALL = smallest balance first (momentum wins). AVALANCHE = highest APR first (saves the most money). Change method in G5:H5. Extra payment in G6:H6 speeds up your payoff.
B5: ⚙️ PAYOFF METHOD — type SNOWBALL or AVALANCHE in the yellow cell: | G5: SNOWBALL | I5: ← type here
B6: 💵 Extra monthly payment to throw at priority debt ($): | G6: 0
B8: CREDITOR / DEBT NAME | C8: CURRENT BALANCE | D8: INTEREST RATE (APR) | E8: MIN. PAYMENT | F8: MONTHS TO PAYOFF (min pmt only) | G8: TOTAL INTEREST (min pmt only) | H8: EST. PAYOFF DATE (min pmt only) | I8: SNOWBALL RANK | J8: AVALANCHE RANK
B9: e.g. Credit Card 1 | F9: =IF(OR(NOT(ISNUMBER(C9)),C9=0,NOT(ISNUMBER(E9)),E9=0),"-",IF(OR(NOT(ISNUMBER(D9)),D9=0),IFERROR(CEILING(C9/E9,1),"-"),IFERROR(CEILING(-LN(1-(C9*(D9/12))/E9)/LN(1+(D9/12)),1),"-"))) -> - | G9: =IF(OR(NOT(ISNUMBER(F9)),F9="-"),"-",IFERROR(MAX(0,E9*F9-C9),"-")) -> - | H9: =IF(OR(NOT(ISNUMBER(F9)),F9="-"),"-",TEXT(EDATE(TODAY(),F9),"mmm YYYY")) -> - | I9: =IF(OR(NOT(ISNUMBER(C9)),C9=0),"-",SUMPRODUCT((C9:C18>0)*ISNUMBER(C9:C18)*(C9:C18<C9))+1) -> - | J9: =IF(OR(NOT(ISNUMBER(D9)),D9=0),"-",SUMPRODUCT((D9:D18>0)*ISNUMBER(D9:D18)*(D9:D18>D9))+1) -> -
B10: e.g. Car Loan | F10: =IF(OR(NOT(ISNUMBER(C10)),C10=0,NOT(ISNUMBER(E10)),E10=0),"-",IF(OR(NOT(ISNUMBER(D10)),D10=0),IFERROR(CEILING(C10/E10,1),"-"),IFERROR(CEILING(-LN(1-(C10*(D10/12))/E10)/LN(1+(D10/12)),1),"-"))) -> - | G10: =IF(OR(NOT(ISNUMBER(F10)),F10="-"),"-",IFERROR(MAX(0,E10*F10-C10),"-")) -> - | H10: =IF(OR(NOT(ISNUMBER(F10)),F10="-"),"-",TEXT(EDATE(TODAY(),F10),"mmm YYYY")) -> - | I10: =IF(OR(NOT(ISNUMBER(C10)),C10=0),"-",SUMPRODUCT((C9:C18>0)*ISNUMBER(C9:C18)*(C9:C18<C10))+1) -> - | J10: =IF(OR(NOT(ISNUMBER(D10)),D10=0),"-",SUMPRODUCT((D9:D18>0)*ISNUMBER(D9:D18)*(D9:D18>D10))+1) -> -
B11: e.g. Student Loan | F11: =IF(OR(NOT(ISNUMBER(C11)),C11=0,NOT(ISNUMBER(E11)),E11=0),"-",IF(OR(NOT(ISNUMBER(D11)),D11=0),IFERROR(CEILING(C11/E11,1),"-"),IFERROR(CEILING(-LN(1-(C11*(D11/12))/E11)/LN(1+(D11/12)),1),"-"))) -> - | G11: =IF(OR(NOT(ISNUMBER(F11)),F11="-"),"-",IFERROR(MAX(0,E11*F11-C11),"-")) -> - | H11: =IF(OR(NOT(ISNUMBER(F11)),F11="-"),"-",TEXT(EDATE(TODAY(),F11),"mmm YYYY")) -> - | I11: =IF(OR(NOT(ISNUMBER(C11)),C11=0),"-",SUMPRODUCT((C9:C18>0)*ISNUMBER(C9:C18)*(C9:C18<C11))+1) -> - | J11: =IF(OR(NOT(ISNUMBER(D11)),D11=0),"-",SUMPRODUCT((D9:D18>0)*ISNUMBER(D9:D18)*(D9:D18>D11))+1) -> -
B12: e.g. Medical Bill | F12: =IF(OR(NOT(ISNUMBER(C12)),C12=0,NOT(ISNUMBER(E12)),E12=0),"-",IF(OR(NOT(ISNUMBER(D12)),D12=0),IFERROR(CEILING(C12/E12,1),"-"),IFERROR(CEILING(-LN(1-(C12*(D12/12))/E12)/LN(1+(D12/12)),1),"-"))) -> - | G12: =IF(OR(NOT(ISNUMBER(F12)),F12="-"),"-",IFERROR(MAX(0,E12*F12-C12),"-")) -> - | H12: =IF(OR(NOT(ISNUMBER(F12)),F12="-"),"-",TEXT(EDATE(TODAY(),F12),"mmm YYYY")) -> - | I12: =IF(OR(NOT(ISNUMBER(C12)),C12=0),"-",SUMPRODUCT((C9:C18>0)*ISNUMBER(C9:C18)*(C9:C18<C12))+1) -> - | J12: =IF(OR(NOT(ISNUMBER(D12)),D12=0),"-",SUMPRODUCT((D9:D18>0)*ISNUMBER(D9:D18)*(D9:D18>D12))+1) -> -
B13: e.g. Personal Loan | F13: =IF(OR(NOT(ISNUMBER(C13)),C13=0,NOT(ISNUMBER(E13)),E13=0),"-",IF(OR(NOT(ISNUMBER(D13)),D13=0),IFERROR(CEILING(C13/E13,1),"-"),IFERROR(CEILING(-LN(1-(C13*(D13/12))/E13)/LN(1+(D13/12)),1),"-"))) -> - | G13: =IF(OR(NOT(ISNUMBER(F13)),F13="-"),"-",IFERROR(MAX(0,E13*F13-C13),"-")) -> - | H13: =IF(OR(NOT(ISNUMBER(F13)),F13="-"),"-",TEXT(EDATE(TODAY(),F13),"mmm YYYY")) -> - | I13: =IF(OR(NOT(ISNUMBER(C13)),C13=0),"-",SUMPRODUCT((C9:C18>0)*ISNUMBER(C9:C18)*(C9:C18<C13))+1) -> - | J13: =IF(OR(NOT(ISNUMBER(D13)),D13=0),"-",SUMPRODUCT((D9:D18>0)*ISNUMBER(D9:D18)*(D9:D18>D13))+1) -> -
F14: =IF(OR(NOT(ISNUMBER(C14)),C14=0,NOT(ISNUMBER(E14)),E14=0),"-",IF(OR(NOT(ISNUMBER(D14)),D14=0),IFERROR(CEILING(C14/E14,1),"-"),IFERROR(CEILING(-LN(1-(C14*(D14/12))/E14)/LN(1+(D14/12)),1),"-"))) -> - | G14: =IF(OR(NOT(ISNUMBER(F14)),F14="-"),"-",IFERROR(MAX(0,E14*F14-C14),"-")) -> - | H14: =IF(OR(NOT(ISNUMBER(F14)),F14="-"),"-",TEXT(EDATE(TODAY(),F14),"mmm YYYY")) -> - | I14: =IF(OR(NOT(ISNUMBER(C14)),C14=0),"-",SUMPRODUCT((C9:C18>0)*ISNUMBER(C9:C18)*(C9:C18<C14))+1) -> - | J14: =IF(OR(NOT(ISNUMBER(D14)),D14=0),"-",SUMPRODUCT((D9:D18>0)*ISNUMBER(D9:D18)*(D9:D18>D14))+1) -> -
F15: =IF(OR(NOT(ISNUMBER(C15)),C15=0,NOT(ISNUMBER(E15)),E15=0),"-",IF(OR(NOT(ISNUMBER(D15)),D15=0),IFERROR(CEILING(C15/E15,1),"-"),IFERROR(CEILING(-LN(1-(C15*(D15/12))/E15)/LN(1+(D15/12)),1),"-"))) -> - | G15: =IF(OR(NOT(ISNUMBER(F15)),F15="-"),"-",IFERROR(MAX(0,E15*F15-C15),"-")) -> - | H15: =IF(OR(NOT(ISNUMBER(F15)),F15="-"),"-",TEXT(EDATE(TODAY(),F15),"mmm YYYY")) -> - | I15: =IF(OR(NOT(ISNUMBER(C15)),C15=0),"-",SUMPRODUCT((C9:C18>0)*ISNUMBER(C9:C18)*(C9:C18<C15))+1) -> - | J15: =IF(OR(NOT(ISNUMBER(D15)),D15=0),"-",SUMPRODUCT((D9:D18>0)*ISNUMBER(D9:D18)*(D9:D18>D15))+1) -> -
F16: =IF(OR(NOT(ISNUMBER(C16)),C16=0,NOT(ISNUMBER(E16)),E16=0),"-",IF(OR(NOT(ISNUMBER(D16)),D16=0),IFERROR(CEILING(C16/E16,1),"-"),IFERROR(CEILING(-LN(1-(C16*(D16/12))/E16)/LN(1+(D16/12)),1),"-"))) -> - | G16: =IF(OR(NOT(ISNUMBER(F16)),F16="-"),"-",IFERROR(MAX(0,E16*F16-C16),"-")) -> - | H16: =IF(OR(NOT(ISNUMBER(F16)),F16="-"),"-",TEXT(EDATE(TODAY(),F16),"mmm YYYY")) -> - | I16: =IF(OR(NOT(ISNUMBER(C16)),C16=0),"-",SUMPRODUCT((C9:C18>0)*ISNUMBER(C9:C18)*(C9:C18<C16))+1) -> - | J16: =IF(OR(NOT(ISNUMBER(D16)),D16=0),"-",SUMPRODUCT((D9:D18>0)*ISNUMBER(D9:D18)*(D9:D18>D16))+1) -> -
F17: =IF(OR(NOT(ISNUMBER(C17)),C17=0,NOT(ISNUMBER(E17)),E17=0),"-",IF(OR(NOT(ISNUMBER(D17)),D17=0),IFERROR(CEILING(C17/E17,1),"-"),IFERROR(CEILING(-LN(1-(C17*(D17/12))/E17)/LN(1+(D17/12)),1),"-"))) -> - | G17: =IF(OR(NOT(ISNUMBER(F17)),F17="-"),"-",IFERROR(MAX(0,E17*F17-C17),"-")) -> - | H17: =IF(OR(NOT(ISNUMBER(F17)),F17="-"),"-",TEXT(EDATE(TODAY(),F17),"mmm YYYY")) -> - | I17: =IF(OR(NOT(ISNUMBER(C17)),C17=0),"-",SUMPRODUCT((C9:C18>0)*ISNUMBER(C9:C18)*(C9:C18<C17))+1) -> - | J17: =IF(OR(NOT(ISNUMBER(D17)),D17=0),"-",SUMPRODUCT((D9:D18>0)*ISNUMBER(D9:D18)*(D9:D18>D17))+1) -> -
F18: =IF(OR(NOT(ISNUMBER(C18)),C18=0,NOT(ISNUMBER(E18)),E18=0),"-",IF(OR(NOT(ISNUMBER(D18)),D18=0),IFERROR(CEILING(C18/E18,1),"-"),IFERROR(CEILING(-LN(1-(C18*(D18/12))/E18)/LN(1+(D18/12)),1),"-"))) -> - | G18: =IF(OR(NOT(ISNUMBER(F18)),F18="-"),"-",IFERROR(MAX(0,E18*F18-C18),"-")) -> - | H18: =IF(OR(NOT(ISNUMBER(F18)),F18="-"),"-",TEXT(EDATE(TODAY(),F18),"mmm YYYY")) -> - | I18: =IF(OR(NOT(ISNUMBER(C18)),C18=0),"-",SUMPRODUCT((C9:C18>0)*ISNUMBER(C9:C18)*(C9:C18<C18))+1) -> - | J18: =IF(OR(NOT(ISNUMBER(D18)),D18=0),"-",SUMPRODUCT((D9:D18>0)*ISNUMBER(D9:D18)*(D9:D18>D18))+1) -> -
B19: TOTALS | C19: =SUMPRODUCT((ISNUMBER(C9:C18))*(C9:C18>0)*C9:C18) -> 0 | E19: =SUMPRODUCT((ISNUMBER(E9:E18))*(E9:E18>0)*E9:E18) -> 0
B21: 🎯 PRIORITY DEBT (auto-selected by method in G5:H5)
B22: DEBT NAME | D22: BALANCE | F22: APR | G22: MIN PMT + EXTRA/MO | I22: EST. PAYOFF DATE
B23: =IFERROR(IF(UPPER(G5)="AVALANCHE",INDEX(B9:B18,MATCH(1,J9:J18,0)),INDEX(B9:B18,MATCH(1,I9:I18,0))),"— Enter debts above —") -> — Enter debts above — | D23: =IFERROR(IF(UPPER(G5)="AVALANCHE",INDEX(C9:C18,MATCH(1,J9:J18,0)),INDEX(C9:C18,MATCH(1,I9:I18,0))),"") | F23: =IFERROR(IF(UPPER(G5)="AVALANCHE",INDEX(D9:D18,MATCH(1,J9:J18,0)),INDEX(D9:D18,MATCH(1,I9:I18,0))),"") | G23: =IFERROR(IF(UPPER(G5)="AVALANCHE",INDEX(E9:E18,MATCH(1,J9:J18,0))+G6,INDEX(E9:E18,MATCH(1,I9:I18,0))+G6),"") | I23: =IFERROR(IF(UPPER(G5)="AVALANCHE",INDEX(H9:H18,MATCH(1,J9:J18,0)),INDEX(H9:H18,MATCH(1,I9:I18,0))),"")
B25: 📊 DEBT SUMMARY STATS
B26: Total Debt Balance | D26: Total Min Pmts/Mo | F26: Avg. APR | H26: # of Debts
B27: =SUMPRODUCT((ISNUMBER(C9:C18))*(C9:C18>0)*C9:C18) -> 0 | D27: =SUMPRODUCT((ISNUMBER(E9:E18))*(E9:E18>0)*E9:E18) -> 0 | F27: =IFERROR(AVERAGEIF(D9:D18,">0"),0) -> 0 | H27: =SUMPRODUCT((ISNUMBER(C9:C18))*(C9:C18>0)) -> 0
B29: "Know well the condition of your flocks." — Proverbs 27:23 | Track it. Attack it. Pay it off.
B31: ⚖️ SNOWBALL vs. AVALANCHE — SIDE-BY-SIDE COMPARISON
C32: METRIC | D32: SNOWBALL RESULT | G32: AVALANCHE RESULT
C33: Total Interest Paid | D33: =IFERROR(SUMPRODUCT((ISNUMBER(C9:C18))*(C9:C18>0)*IF(ISNUMBER(G9:G18),G9:G18,0)),"Enter debts above") -> 0 | G33: =IFERROR(SUMPRODUCT((ISNUMBER(C9:C18))*(C9:C18>0)*IF(ISNUMBER(G9:G18),G9:G18,0)),"Enter debts above") -> 0
C34: Months to Debt-Free | D34: =IFERROR(MAX(IF(ISNUMBER(F9:F18),F9:F18,0)),"—") -> 0 | G34: =IFERROR(MAX(IF(ISNUMBER(F9:F18),F9:F18,0)),"—") -> 0
C35: Est. Debt-Free Date | D35: =IFERROR(TEXT(EDATE(TODAY(),MAX(IF(ISNUMBER(F9:F18),F9:F18,0))),"mmmm YYYY"),"—") -> June 2026 | G35: =IFERROR(TEXT(EDATE(TODAY(),MAX(IF(ISNUMBER(F9:F18),F9:F18,0))),"mmmm YYYY"),"—") -> June 2026
C36: Best Strategy For | D36: "Quick wins & motivation — smallest balance first" | G36: "Math savings — highest APR first saves the most money"
B37: 💡 INTEREST SAVED (Avalanche vs Snowball): | D37: =IFERROR(SUMPRODUCT((ISNUMBER(C9:C18))*(C9:C18>0)*IF(ISNUMBER(G9:G18),G9:G18,0))-SUMPRODUCT((ISNUMBER(C9:C18))*(C9:C18>0)*IF(ISNUMBER(G9:G18),G9:G18,0)),"Enter debts above") -> 0
B38: "Know well the condition of your flocks." — Proverbs 27:23

Sheet 📈 Payoff Timeline
B1: 📈 PAYOFF TIMELINE — Month-by-Month Progress
B2: Enter debts on the 💸 Debt Tracker tab first. This sheet auto-calculates remaining balance each month.
B3: ⚙️ Extra payment set in Debt Tracker (G6). Method toggled in G5. This timeline applies both to your payoff projection.
B5: 📊 LIVE SNAPSHOT FROM YOUR DEBT TRACKER
B6: Total Debt | C6: ='💸 Debt Tracker'!B27 -> 0 | D6: Min Pmts/Mo | E6: ='💸 Debt Tracker'!D27 -> 0 | F6: Avg APR | G6: ='💸 Debt Tracker'!F27 -> 0 | H6: # of Debts | I6: ='💸 Debt Tracker'!H27 -> 0 | J6: Extra Pmt | K6: ='💸 Debt Tracker'!G6 -> 0
B7: 📅 MONTH-BY-MONTH TRACKER (60 Months)
B8: MONTH # | C8: CALENDAR MONTH | D8: STARTING BALANCE | E8: TOTAL MIN PMT | F8: EXTRA PMT | G8: TOTAL PAID | H8: INTEREST CHARGED | I8: PRINCIPAL PAID | J8: REMAINING BALANCE | K8: % PAID OFF | L8: STATUS
B9: 1 | C9: =TEXT(EDATE(TODAY(),0),"mmm YYYY") -> Jun 2026 | D9: ='💸 Debt Tracker'!B27 -> 0 | E9: ='💸 Debt Tracker'!D27 -> 0 | F9: ='💸 Debt Tracker'!G6 -> 0 | G9: =IF(D9<=0,0,MIN(E9+F9,D9)) -> 0 | H9: =IF(D9<=0,0,ROUND(D9*('💸 Debt Tracker'!F27/12),2)) -> 0 | I9: =IF(D9<=0,0,MAX(0,G9-H9)) -> 0 | J9: =IF(D9<=0,0,MAX(0,D9-I9)) -> 0 | K9: =IF('💸 Debt Tracker'!B27=0,0,MAX(0,1-J9/'💸 Debt Tracker'!B27)) -> 0 | L9: =IF(J9<=0,"🎉 DEBT FREE!",IF(K9>=0.75,"75% — keep pushing!",IF(K9>=0.5,"Halfway — momentum!",IF(K9>=0.25,"25% done — great start!","")))) -> 🎉 DEBT FREE!
B10: 2 | C10: =TEXT(EDATE(TODAY(),1),"mmm YYYY") -> Jul 2026 | D10: =IF(J9<=0,0,J9) -> 0 | E10: ='💸 Debt Tracker'!D27 -> 0 | F10: ='💸 Debt Tracker'!G6 -> 0 | G10: =IF(D10<=0,0,MIN(E10+F10,D10)) -> 0 | H10: =IF(D10<=0,0,ROUND(D10*('💸 Debt Tracker'!F27/12),2)) -> 0 | I10: =IF(D10<=0,0,MAX(0,G10-H10)) -> 0 | J10: =IF(D10<=0,0,MAX(0,D10-I10)) -> 0 | K10: =IF('💸 Debt Tracker'!B27=0,0,MAX(0,1-J10/'💸 Debt Tracker'!B27)) -> 0 | L10: =IF(J10<=0,"🎉 DEBT FREE!",IF(K10>=0.75,"75% — keep pushing!",IF(K10>=0.5,"Halfway — momentum!",IF(K10>=0.25,"25% done — great start!","")))) -> 🎉 DEBT FREE!
B11: 3 | C11: =TEXT(EDATE(TODAY(),2),"mmm YYYY") -> Aug 2026 | D11: =IF(J10<=0,0,J10) -> 0 | E11: ='💸 Debt Tracker'!D27 -> 0 | F11: ='💸 Debt Tracker'!G6 -> 0 | G11: =IF(D11<=0,0,MIN(E11+F11,D11)) -> 0 | H11: =IF(D11<=0,0,ROUND(D11*('💸 Debt Tracker'!F27/12),2)) -> 0 | I11: =IF(D11<=0,0,MAX(0,G11-H11)) -> 0 | J11: =IF(D11<=0,0,MAX(0,D11-I11)) -> 0 | K11: =IF('💸 Debt Tracker'!B27=0,0,MAX(0,1-J11/'💸 Debt Tracker'!B27)) -> 0 | L11: =IF(J11<=0,"🎉 DEBT FREE!",IF(K11>=0.75,"75% — keep pushing!",IF(K11>=0.5,"Halfway — momentum!",IF(K11>=0.25,"25% done — great start!","")))) -> 🎉 DEBT FREE!
B12: 4 | C12: =TEXT(EDATE(TODAY(),3),"mmm YYYY") -> Sep 2026 | D12: =IF(J11<=0,0,J11) -> 0 | E12: ='💸 Debt Tracker'!D27 -> 0 | F12: ='💸 Debt Tracker'!G6 -> 0 | G12: =IF(D12<=0,0,MIN(E12+F12,D12)) -> 0 | H12: =IF(D12<=0,0,ROUND(D12*('💸 Debt Tracker'!F27/12),2)) -> 0 | I12: =IF(D12<=0,0,MAX(0,G12-H12)) -> 0 | J12: =IF(D12<=0,0,MAX(0,D12-I12)) -> 0 | K12: =IF('💸 Debt Tracker'!B27=0,0,MAX(0,1-J12/'💸 Debt Tracker'!B27)) -> 0 | L12: =IF(J12<=0,"🎉 DEBT FREE!",IF(K12>=0.75,"75% — keep pushing!",IF(K12>=0.5,"Halfway — momentum!",IF(K12>=0.25,"25% done — great start!","")))) -> 🎉 DEBT FREE!
B13: 5 | C13: =TEXT(EDATE(TODAY(),4),"mmm YYYY") -> Oct 2026 | D13: =IF(J12<=0,0,J12) -> 0 | E13: ='💸 Debt Tracker'!D27 -> 0 | F13: ='💸 Debt Tracker'!G6 -> 0 | G13: =IF(D13<=0,0,MIN(E13+F13,D13)) -> 0 | H13: =IF(D13<=0,0,ROUND(D13*('💸 Debt Tracker'!F27/12),2)) -> 0 | I13: =IF(D13<=0,0,MAX(0,G13-H13)) -> 0 | J13: =IF(D13<=0,0,MAX(0,D13-I13)) -> 0 | K13: =IF('💸 Debt Tracker'!B27=0,0,MAX(0,1-J13/'💸 Debt Tracker'!B27)) -> 0 | L13: =IF(J13<=0,"🎉 DEBT FREE!",IF(K13>=0.75,"75% — keep pushing!",IF(K13>=0.5,"Halfway — momentum!",IF(K13>=0.25,"25% done — great start!","")))) -> 🎉 DEBT FREE!
B14: 6 | C14: =TEXT(EDATE(TODAY(),5),"mmm YYYY") -> Nov 2026 | D14: =IF(J13<=0,0,J13) -> 0 | E14: ='💸 Debt Tracker'!D27 -> 0 | F14: ='💸 Debt Tracker'!G6 -> 0 | G14: =IF(D14<=0,0,MIN(E14+F14,D14)) -> 0 | H14: =IF(D14<=0,0,ROUND(D14*('💸 Debt Tracker'!F27/12),2)) -> 0 | I14: =IF(D14<=0,0,MAX(0,G14-H14)) -> 0 | J14: =IF(D14<=0,0,MAX(0,D14-I14)) -> 0 | K14: =IF('💸 Debt Tracker'!B27=0,0,MAX(0,1-J14/'💸 Debt Tracker'!B27)) -> 0 | L14: =IF(J14<=0,"🎉 DEBT FREE!",IF(K14>=0.75,"75% — keep pushing!",IF(K14>=0.5,"Halfway — momentum!",IF(K14>=0.25,"25% done — great start!","")))) -> 🎉 DEBT FREE!
B15: 7 | C15: =TEXT(EDATE(TODAY(),6),"mmm YYYY") -> Dec 2026 | D15: =IF(J14<=0,0,J14) -> 0 | E15: ='💸 Debt Tracker'!D27 -> 0 | F15: ='💸 Debt Tracker'!G6 -> 0 | G15: =IF(D15<=0,0,MIN(E15+F15,D15)) -> 0 | H15: =IF(D15<=0,0,ROUND(D15*('💸 Debt Tracker'!F27/12),2)) -> 0 | I15: =IF(D15<=0,0,MAX(0,G15-H15)) -> 0 | J15: =IF(D15<=0,0,MAX(0,D15-I15)) -> 0 | K15: =IF('💸 Debt Tracker'!B27=0,0,MAX(0,1-J15/'💸 Debt Tracker'!B27)) -> 0 | L15: =IF(J15<=0,"🎉 DEBT FREE!",IF(K15>=0.75,"75% — keep pushing!",IF(K15>=0.5,"Halfway — momentum!",IF(K15>=0.25,"25% done — great start!","")))) -> 🎉 DEBT FREE!
B16: 8 | C16: =TEXT(EDATE(TODAY(),7),"mmm YYYY") -> Jan 2027 | D16: =IF(J15<=0,0,J15) -> 0 | E16: ='💸 Debt Tracker'!D27 -> 0 | F16: ='💸 Debt Tracker'!G6 -> 0 | G16: =IF(D16<=0,0,MIN(E16+F16,D16)) -> 0 | H16: =IF(D16<=0,0,ROUND(D16*('💸 Debt Tracker'!F27/12),2)) -> 0 | I16: =IF(D16<=0,0,MAX(0,G16-H16)) -> 0 | J16: =IF(D16<=0,0,MAX(0,D16-I16)) -> 0 | K16: =IF('💸 Debt Tracker'!B27=0,0,MAX(0,1-J16/'💸 Debt Tracker'!B27)) -> 0 | L16: =IF(J16<=0,"🎉 DEBT FREE!",IF(K16>=0.75,"75% — keep pushing!",IF(K16>=0.5,"Halfway — momentum!",IF(K16>=0.25,"25% done — great start!","")))) -> 🎉 DEBT FREE!
B17: 9 | C17: =TEXT(EDATE(TODAY(),8),"mmm YYYY") -> Feb 2027 | D17: =IF(J16<=0,0,J16) -> 0 | E17: ='💸 Debt Tracker'!D27 -> 0 | F17: ='💸 Debt Tracker'!G6 -> 0 | G17: =IF(D17<=0,0,MIN(E17+F17,D17)) -> 0 | H17: =IF(D17<=0,0,ROUND(D17*('💸 Debt Tracker'!F27/12),2)) -> 0 | I17: =IF(D17<=0,0,MAX(0,G17-H17)) -> 0 | J17: =IF(D17<=0,0,MAX(0,D17-I17)) -> 0 | K17: =IF('💸 Debt Tracker'!B27=0,0,MAX(0,1-J17/'💸 Debt Tracker'!B27)) -> 0 | L17: =IF(J17<=0,"🎉 DEBT FREE!",IF(K17>=0.75,"75% — keep pushing!",IF(K17>=0.5,"Halfway — momentum!",IF(K17>=0.25,"25% done — great start!","")))) -> 🎉 DEBT FREE!
B18: 10 | C18: =TEXT(EDATE(TODAY(),9),"mmm YYYY") -> Mar 2027 | D18: =IF(J17<=0,0,J17) -> 0 | E18: ='💸 Debt Tracker'!D27 -> 0 | F18: ='💸 Debt Tracker'!G6 -> 0 | G18: =IF(D18<=0,0,MIN(E18+F18,D18)) -> 0 | H18: =IF(D18<=0,0,ROUND(D18*('💸 Debt Tracker'!F27/12),2)) -> 0 | I18: =IF(D18<=0,0,MAX(0,G18-H18)) -> 0 | J18: =IF(D18<=0,0,MAX(0,D18-I18)) -> 0 | K18: =IF('💸 Debt Tracker'!B27=0,0,MAX(0,1-J18/'💸 Debt Tracker'!B27)) -> 0 | L18: =IF(J18<=0,"🎉 DEBT FREE!",IF(K18>=0.75,"75% — keep pushing!",IF(K18>=0.5,"Halfway — momentum!",IF(K18>=0.25,"25% done — great start!","")))) -> 🎉 DEBT FREE!
B19: 11 | C19: =TEXT(EDATE(TODAY(),10),"mmm YYYY") -> Apr 2027 | D19: =IF(J18<=0,0,J18) -> 0 | E19: ='💸 Debt Tracker'!D27 -> 0 | F19: ='💸 Debt Tracker'!G6 -> 0 | G19: =IF(D19<=0,0,MIN(E19+F19,D19)) -> 0 | H19: =IF(D19<=0,0,ROUND(D19*('💸 Debt Tracker'!F27/12),2)) -> 0 | I19: =IF(D19<=0,0,MAX(0,G19-H19)) -> 0 | J19: =IF(D19<=0,0,MAX(0,D19-I19)) -> 0 | K19: =IF('💸 Debt Tracker'!B27=0,0,MAX(0,1-J19/'💸 Debt Tracker'!B27)) -> 0 | L19: =IF(J19<=0,"🎉 DEBT FREE!",IF(K19>=0.75,"75% — keep pushing!",IF(K19>=0.5,"Halfway — momentum!",IF(K19>=0.25,"25% done — great start!","")))) -> 🎉 DEBT FREE!
B20: 12 | C20: =TEXT(EDATE(TODAY(),11),"mmm YYYY") -> May 2027 | D20: =IF(J19<=0,0,J19) -> 0 | E20: ='💸 Debt Tracker'!D27 -> 0 | F20: ='💸 Debt Tracker'!G6 -> 0 | G20: =IF(D20<=0,0,MIN(E20+F20,D20)) -> 0 | H20: =IF(D20<=0,0,ROUND(D20*('💸 Debt Tracker'!F27/12),2)) -> 0 | I20: =IF(D20<=0,0,MAX(0,G20-H20)) -> 0 | J20: =IF(D20<=0,0,MAX(0,D20-I20)) -> 0 | K20: =IF('💸 Debt Tracker'!B27=0,0,MAX(0,1-J20/'💸 Debt Tracker'!B27)) -> 0 | L20: =IF(J20<=0,"🎉 DEBT FREE!",IF(K20>=0.75,"75% — keep pushing!",IF(K20>=0.5,"Halfway — momentum!",IF(K20>=0.25,"25% done — great start!","")))) -> 🎉 DEBT FREE!
B21: 13 | C21: =TEXT(EDATE(TODAY(),12),"mmm YYYY") -> Jun 2027 | D21: =IF(J20<=0,0,J20) -> 0 | E21: ='💸 Debt Tracker'!D27 -> 0 | F21: ='💸 Debt Tracker'!G6 -> 0 | G21: =IF(D21<=0,0,MIN(E21+F21,D21)) -> 0 | H21: =IF(D21<=0,0,ROUND(D21*('💸 Debt Tracker'!F27/12),2)) -> 0 | I21: =IF(D21<=0,0,MAX(0,G21-H21)) -> 0 | J21: =IF(D21<=0,0,MAX(0,D21-I21)) -> 0 | K21: =IF('💸 Debt Tracker'!B27=0,0,MAX(0,1-J21/'💸 Debt Tracker'!B27)) -> 0 | L21: =IF(J21<=0,"🎉 DEBT FREE!",IF(K21>=0.75,"75% — keep pushing!",IF(K21>=0.5,"Halfway — momentum!",IF(K21>=0.25,"25% done — great start!","")))) -> 🎉 DEBT FREE!
B22: 14 | C22: =TEXT(EDATE(TODAY(),13),"mmm YYYY") -> Jul 2027 | D22: =IF(J21<=0,0,J21) -> 0 | E22: ='💸 Debt Tracker'!D27 -> 0 | F22: ='💸 Debt Tracker'!G6 -> 0 | G22: =IF(D22<=0,0,MIN(E22+F22,D22)) -> 0 | H22: =IF(D22<=0,0,ROUND(D22*('💸 Debt Tracker'!F27/12),2)) -> 0 | I22: =IF(D22<=0,0,MAX(0,G22-H22)) -> 0 | J22: =IF(D22<=0,0,MAX(0,D22-I22)) -> 0 | K22: =IF('💸 Debt Tracker'!B27=0,0,MAX(0,1-J22/'💸 Debt Tracker'!B27)) -> 0 | L22: =IF(J22<=0,"🎉 DEBT FREE!",IF(K22>=0.75,"75% — keep pushing!",IF(K22>=0.5,"Halfway — momentum!",IF(K22>=0.25,"25% done — great start!","")))) -> 🎉 DEBT FREE!
B23: 15 | C23: =TEXT(EDATE(TODAY(),14),"mmm YYYY") -> Aug 2027 | D23: =IF(J22<=0,0,J22) -> 0 | E23: ='💸 Debt Tracker'!D27 -> 0 | F23: ='💸 Debt Tracker'!G6 -> 0 | G23: =IF(D23<=0,0,MIN(E23+F23,D23)) -> 0 | H23: =IF(D23<=0,0,ROUND(D23*('💸 Debt Tracker'!F27/12),2)) -> 0 | I23: =IF(D23<=0,0,MAX(0,G23-H23)) -> 0 | J23: =IF(D23<=0,0,MAX(0,D23-I23)) -> 0 | K23: =IF('💸 Debt Tracker'!B27=0,0,MAX(0,1-J23/'💸 Debt Tracker'!B27)) -> 0 | L23: =IF(J23<=0,"🎉 DEBT FREE!",IF(K23>=0.75,"75% — keep pushing!",IF(K23>=0.5,"Halfway — momentum!",IF(K23>=0.25,"25% done — great start!","")))) -> 🎉 DEBT FREE!
B24: 16 | C24: =TEXT(EDATE(TODAY(),15),"mmm YYYY") -> Sep 2027 | D24: =IF(J23<=0,0,J23) -> 0 | E24: ='💸 Debt Tracker'!D27 -> 0 | F24: ='💸 Debt Tracker'!G6 -> 0 | G24: =IF(D24<=0,0,MIN(E24+F24,D24)) -> 0 | H24: =IF(D24<=0,0,ROUND(D24*('💸 Debt Tracker'!F27/12),2)) -> 0 | I24: =IF(D24<=0,0,MAX(0,G24-H24)) -> 0 | J24: =IF(D24<=0,0,MAX(0,D24-I24)) -> 0 | K24: =IF('💸 Debt Tracker'!B27=0,0,MAX(0,1-J24/'💸 Debt Tracker'!B27)) -> 0 | L24: =IF(J24<=0,"🎉 DEBT FREE!",IF(K24>=0.75,"75% — keep pushing!",IF(K24>=0.5,"Halfway — momentum!",IF(K24>=0.25,"25% done — great start!","")))) -> 🎉 DEBT FREE!
B25: 17 | C25: =TEXT(EDATE(TODAY(),16),"mmm YYYY") -> Oct 2027 | D25: =IF(J24<=0,0,J24) -> 0 | E25: ='💸 Debt Tracker'!D27 -> 0 | F25: ='💸 Debt Tracker'!G6 -> 0 | G25: =IF(D25<=0,0,MIN(E25+F25,D25)) -> 0 | H25: =IF(D25<=0,0,ROUND(D25*('💸 Debt Tracker'!F27/12),2)) -> 0 | I25: =IF(D25<=0,0,MAX(0,G25-H25)) -> 0 | J25: =IF(D25<=0,0,MAX(0,D25-I25)) -> 0 | K25: =IF('💸 Debt Tracker'!B27=0,0,MAX(0,1-J25/'💸 Debt Tracker'!B27)) -> 0 | L25: =IF(J25<=0,"🎉 DEBT FREE!",IF(K25>=0.75,"75% — keep pushing!",IF(K25>=0.5,"Halfway — momentum!",IF(K25>=0.25,"25% done — great start!","")))) -> 🎉 DEBT FREE!
B26: 18 | C26: =TEXT(EDATE(TODAY(),17),"mmm YYYY") -> Nov 2027 | D26: =IF(J25<=0,0,J25) -> 0 | E26: ='💸 Debt Tracker'!D27 -> 0 | F26: ='💸 Debt Tracker'!G6 -> 0 | G26: =IF(D26<=0,0,MIN(E26+F26,D26)) -> 0 | H26: =IF(D26<=0,0,ROUND(D26*('💸 Debt Tracker'!F27/12),2)) -> 0 | I26: =IF(D26<=0,0,MAX(0,G26-H26)) -> 0 | J26: =IF(D26<=0,0,MAX(0,D26-I26)) -> 0 | K26: =IF('💸 Debt Tracker'!B27=0,0,MAX(0,1-J26/'💸 Debt Tracker'!B27)) -> 0 | L26: =IF(J26<=0,"🎉 DEBT FREE!",IF(K26>=0.75,"75% — keep pushing!",IF(K26>=0.5,"Halfway — momentum!",IF(K26>=0.25,"25% done — great start!","")))) -> 🎉 DEBT FREE!
B27: 19 | C27: =TEXT(EDATE(TODAY(),18),"mmm YYYY") -> Dec 2027 | D27: =IF(J26<=0,0,J26) -> 0 | E27: ='💸 Debt Tracker'!D27 -> 0 | F27: ='💸 Debt Tracker'!G6 -> 0 | G27: =IF(D27<=0,0,MIN(E27+F27,D27)) -> 0 | H27: =IF(D27<=0,0,ROUND(D27*('💸 Debt Tracker'!F27/12),2)) -> 0 | I27: =IF(D27<=0,0,MAX(0,G27-H27)) -> 0 | J27: =IF(D27<=0,0,MAX(0,D27-I27)) -> 0 | K27: =IF('💸 Debt Tracker'!B27=0,0,MAX(0,1-J27/'💸 Debt Tracker'!B27)) -> 0 | L27: =IF(J27<=0,"🎉 DEBT FREE!",IF(K27>=0.75,"75% — keep pushing!",IF(K27>=0.5,"Halfway — momentum!",IF(K27>=0.25,"25% done — great start!","")))) -> 🎉 DEBT FREE!
B28: 20 | C28: =TEXT(EDATE(TODAY(),19),"mmm YYYY") -> Jan 2028 | D28: =IF(J27<=0,0,J27) -> 0 | E28: ='💸 Debt Tracker'!D27 -> 0 | F28: ='💸 Debt Tracker'!G6 -> 0 | G28: =IF(D28<=0,0,MIN(E28+F28,D28)) -> 0 | H28: =IF(D28<=0,0,ROUND(D28*('💸 Debt Tracker'!F27/12),2)) -> 0 | I28: =IF(D28<=0,0,MAX(0,G28-H28)) -> 0 | J28: =IF(D28<=0,0,MAX(0,D28-I28)) -> 0 | K28: =IF('💸 Debt Tracker'!B27=0,0,MAX(0,1-J28/'💸 Debt Tracker'!B27)) -> 0 | L28: =IF(J28<=0,"🎉 DEBT FREE!",IF(K28>=0.75,"75% — keep pushing!",IF(K28>=0.5,"Halfway — momentum!",IF(K28>=0.25,"25% done — great start!","")))) -> 🎉 DEBT FREE!
B29: 21 | C29: =TEXT(EDATE(TODAY(),20),"mmm YYYY") -> Feb 2028 | D29: =IF(J28<=0,0,J28) -> 0 | E29: ='💸 Debt Tracker'!D27 -> 0 | F29: ='💸 Debt Tracker'!G6 -> 0 | G29: =IF(D29<=0,0,MIN(E29+F29,D29)) -> 0 | H29: =IF(D29<=0,0,ROUND(D29*('💸 Debt Tracker'!F27/12),2)) -> 0 | I29: =IF(D29<=0,0,MAX(0,G29-H29)) -> 0 | J29: =IF(D29<=0,0,MAX(0,D29-I29)) -> 0 | K29: =IF('💸 Debt Tracker'!B27=0,0,MAX(0,1-J29/'💸 Debt Tracker'!B27)) -> 0 | L29: =IF(J29<=0,"🎉 DEBT FREE!",IF(K29>=0.75,"75% — keep pushing!",IF(K29>=0.5,"Halfway — momentum!",IF(K29>=0.25,"25% done — great start!","")))) -> 🎉 DEBT FREE!
B30: 22 | C30: =TEXT(EDATE(TODAY(),21),"mmm YYYY") -> Mar 2028 | D30: =IF(J29<=0,0,J29) -> 0 | E30: ='💸 Debt Tracker'!D27 -> 0 | F30: ='💸 Debt Tracker'!G6 -> 0 | G30: =IF(D30<=0,0,MIN(E30+F30,D30)) -> 0 | H30: =IF(D30<=0,0,ROUND(D30*('💸 Debt Tracker'!F27/12),2)) -> 0 | I30: =IF(D30<=0,0,MAX(0,G30-H30)) -> 0 | J30: =IF(D30<=0,0,MAX(0,D30-I30)) -> 0 | K30: =IF('💸 Debt Tracker'!B27=0,0,MAX(0,1-J30/'💸 Debt Tracker'!B27)) -> 0 | L30: =IF(J30<=0,"🎉 DEBT FREE!",IF(K30>=0.75,"75% — keep pushing!",IF(K30>=0.5,"Halfway — momentum!",IF(K30>=0.25,"25% done — great start!","")))) -> 🎉 DEBT FREE!
B31: 23 | C31: =TEXT(EDATE(TODAY(),22),"mmm YYYY") -> Apr 2028 | D31: =IF(J30<=0,0,J30) -> 0 | E31: ='💸 Debt Tracker'!D27 -> 0 | F31: ='💸 Debt Tracker'!G6 -> 0 | G31: =IF(D31<=0,0,MIN(E31+F31,D31)) -> 0 | H31: =IF(D31<=0,0,ROUND(D31*('💸 Debt Tracker'!F27/12),2)) -> 0 | I31: =IF(D31<=0,0,MAX(0,G31-H31)) -> 0 | J31: =IF(D31<=0,0,MAX(0,D31-I31)) -> 0 | K31: =IF('💸 Debt Tracker'!B27=0,0,MAX(0,1-J31/'💸 Debt Tracker'!B27)) -> 0 | L31: =IF(J31<=0,"🎉 DEBT FREE!",IF(K31>=0.75,"75% — keep pushing!",IF(K31>=0.5,"Halfway — momentum!",IF(K31>=0.25,"25% done — great start!","")))) -> 🎉 DEBT FREE!
B32: 24 | C32: =TEXT(EDATE(TODAY(),23),"mmm YYYY") -> May 2028 | D32: =IF(J31<=0,0,J31) -> 0 | E32: ='💸 Debt Tracker'!D27 -> 0 | F32: ='💸 Debt Tracker'!G6 -> 0 | G32: =IF(D32<=0,0,MIN(E32+F32,D32)) -> 0 | H32: =IF(D32<=0,0,ROUND(D32*('💸 Debt Tracker'!F27/12),2)) -> 0 | I32: =IF(D32<=0,0,MAX(0,G32-H32)) -> 0 | J32: =IF(D32<=0,0,MAX(0,D32-I32)) -> 0 | K32: =IF('💸 Debt Tracker'!B27=0,0,MAX(0,1-J32/'💸 Debt Tracker'!B27)) -> 0 | L32: =IF(J32<=0,"🎉 DEBT FREE!",IF(K32>=0.75,"75% — keep pushing!",IF(K32>=0.5,"Halfway — momentum!",IF(K32>=0.25,"25% done — great start!","")))) -> 🎉 DEBT FREE!
B33: 25 | C33: =TEXT(EDATE(TODAY(),24),"mmm YYYY") -> Jun 2028 | D33: =IF(J32<=0,0,J32) -> 0 | E33: ='💸 Debt Tracker'!D27 -> 0 | F33: ='💸 Debt Tracker'!G6 -> 0 | G33: =IF(D33<=0,0,MIN(E33+F33,D33)) -> 0 | H33: =IF(D33<=0,0,ROUND(D33*('💸 Debt Tracker'!F27/12),2)) -> 0 | I33: =IF(D33<=0,0,MAX(0,G33-H33)) -> 0 | J33: =IF(D33<=0,0,MAX(0,D33-I33)) -> 0 | K33: =IF('💸 Debt Tracker'!B27=0,0,MAX(0,1-J33/'💸 Debt Tracker'!B27)) -> 0 | L33: =IF(J33<=0,"🎉 DEBT FREE!",IF(K33>=0.75,"75% — keep pushing!",IF(K33>=0.5,"Halfway — momentum!",IF(K33>=0.25,"25% done — great start!","")))) -> 🎉 DEBT FREE!
B34: 26 | C34: =TEXT(EDATE(TODAY(),25),"mmm YYYY") -> Jul 2028 | D34: =IF(J33<=0,0,J33) -> 0 | E34: ='💸 Debt Tracker'!D27 -> 0 | F34: ='💸 Debt Tracker'!G6 -> 0 | G34: =IF(D34<=0,0,MIN(E34+F34,D34)) -> 0 | H34: =IF(D34<=0,0,ROUND(D34*('💸 Debt Tracker'!F27/12),2)) -> 0 | I34: =IF(D34<=0,0,MAX(0,G34-H34)) -> 0 | J34: =IF(D34<=0,0,MAX(0,D34-I34)) -> 0 | K34: =IF('💸 Debt Tracker'!B27=0,0,MAX(0,1-J34/'💸 Debt Tracker'!B27)) -> 0 | L34: =IF(J34<=0,"🎉 DEBT FREE!",IF(K34>=0.75,"75% — keep pushing!",IF(K34>=0.5,"Halfway — momentum!",IF(K34>=0.25,"25% done — great start!","")))) -> 🎉 DEBT FREE!
B35: 27 | C35: =TEXT(EDATE(TODAY(),26),"mmm YYYY") -> Aug 2028 | D35: =IF(J34<=0,0,J34) -> 0 | E35: ='💸 Debt Tracker'!D27 -> 0 | F35: ='💸 Debt Tracker'!G6 -> 0 | G35: =IF(D35<=0,0,MIN(E35+F35,D35)) -> 0 | H35: =IF(D35<=0,0,ROUND(D35*('💸 Debt Tracker'!F27/12),2)) -> 0 | I35: =IF(D35<=0,0,MAX(0,G35-H35)) -> 0 | J35: =IF(D35<=0,0,MAX(0,D35-I35)) -> 0 | K35: =IF('💸 Debt Tracker'!B27=0,0,MAX(0,1-J35/'💸 Debt Tracker'!B27)) -> 0 | L35: =IF(J35<=0,"🎉 DEBT FREE!",IF(K35>=0.75,"75% — keep pushing!",IF(K35>=0.5,"Halfway — momentum!",IF(K35>=0.25,"25% done — great start!","")))) -> 🎉 DEBT FREE!
B36: 28 | C36: =TEXT(EDATE(TODAY(),27),"mmm YYYY") -> Sep 2028 | D36: =IF(J35<=0,0,J35) -> 0 | E36: ='💸 Debt Tracker'!D27 -> 0 | F36: ='💸 Debt Tracker'!G6 -> 0 | G36: =IF(D36<=0,0,MIN(E36+F36,D36)) -> 0 | H36: =IF(D36<=0,0,ROUND(D36*('💸 Debt Tracker'!F27/12),2)) -> 0 | I36: =IF(D36<=0,0,MAX(0,G36-H36)) -> 0 | J36: =IF(D36<=0,0,MAX(0,D36-I36)) -> 0 | K36: =IF('💸 Debt Tracker'!B27=0,0,MAX(0,1-J36/'💸 Debt Tracker'!B27)) -> 0 | L36: =IF(J36<=0,"🎉 DEBT FREE!",IF(K36>=0.75,"75% — keep pushing!",IF(K36>=0.5,"Halfway — momentum!",IF(K36>=0.25,"25% done — great start!","")))) -> 🎉 DEBT FREE!
B37: 29 | C37: =TEXT(EDATE(TODAY(),28),"mmm YYYY") -> Oct 2028 | D37: =IF(J36<=0,0,J36) -> 0 | E37: ='💸 Debt Tracker'!D27 -> 0 | F37: ='💸 Debt Tracker'!G6 -> 0 | G37: =IF(D37<=0,0,MIN(E37+F37,D37)) -> 0 | H37: =IF(D37<=0,0,ROUND(D37*('💸 Debt Tracker'!F27/12),2)) -> 0 | I37: =IF(D37<=0,0,MAX(0,G37-H37)) -> 0 | J37: =IF(D37<=0,0,MAX(0,D37-I37)) -> 0 | K37: =IF('💸 Debt Tracker'!B27=0,0,MAX(0,1-J37/'💸 Debt Tracker'!B27)) -> 0 | L37: =IF(J37<=0,"🎉 DEBT FREE!",IF(K37>=0.75,"75% — keep pushing!",IF(K37>=0.5,"Halfway — momentum!",IF(K37>=0.25,"25% done — great start!","")))) -> 🎉 DEBT FREE!
B38: 30 | C38: =TEXT(EDATE(TODAY(),29),"mmm YYYY") -> Nov 2028 | D38: =IF(J37<=0,0,J37) -> 0 | E38: ='💸 Debt Tracker'!D27 -> 0 | F38: ='💸 Debt Tracker'!G6 -> 0 | G38: =IF(D38<=0,0,MIN(E38+F38,D38)) -> 0 | H38: =IF(D38<=0,0,ROUND(D38*('💸 Debt Tracker'!F27/12),2)) -> 0 | I38: =IF(D38<=0,0,MAX(0,G38-H38)) -> 0 | J38: =IF(D38<=0,0,MAX(0,D38-I38)) -> 0 | K38: =IF('💸 Debt Tracker'!B27=0,0,MAX(0,1-J38/'💸 Debt Tracker'!B27)) -> 0 | L38: =IF(J38<=0,"🎉 DEBT FREE!",IF(K38>=0.75,"75% — keep pushing!",IF(K38>=0.5,"Halfway — momentum!",IF(K38>=0.25,"25% done — great start!","")))) -> 🎉 DEBT FREE!
B39: 31 | C39: =TEXT(EDATE(TODAY(),30),"mmm YYYY") -> Dec 2028 | D39: =IF(J38<=0,0,J38) -> 0 | E39: ='💸 Debt Tracker'!D27 -> 0 | F39: ='💸 Debt Tracker'!G6 -> 0 | G39: =IF(D39<=0,0,MIN(E39+F39,D39)) -> 0 | H39: =IF(D39<=0,0,ROUND(D39*('💸 Debt Tracker'!F27/12),2)) -> 0 | I39: =IF(D39<=0,0,MAX(0,G39-H39)) -> 0 | J39: =IF(D39<=0,0,MAX(0,D39-I39)) -> 0 | K39: =IF('💸 Debt Tracker'!B27=0,0,MAX(0,1-J39/'💸 Debt Tracker'!B27)) -> 0 | L39: =IF(J39<=0,"🎉 DEBT FREE!",IF(K39>=0.75,"75% — keep pushing!",IF(K39>=0.5,"Halfway — momentum!",IF(K39>=0.25,"25% done — great start!","")))) -> 🎉 DEBT FREE!
B40: 32 | C40: =TEXT(EDATE(TODAY(),31),"mmm YYYY") -> Jan 2029 | D40: =IF(J39<=0,0,J39) -> 0 | E40: ='💸 Debt Tracker'!D27 -> 0 | F40: ='💸 Debt Tracker'!G6 -> 0 | G40: =IF(D40<=0,0,MIN(E40+F40,D40)) -> 0 | H40: =IF(D40<=0,0,ROUND(D40*('💸 Debt Tracker'!F27/12),2)) -> 0 | I40: =IF(D40<=0,0,MAX(0,G40-H40)) -> 0 | J40: =IF(D40<=0,0,MAX(0,D40-I40)) -> 0 | K40: =IF('💸 Debt Tracker'!B27=0,0,MAX(0,1-J40/'💸 Debt Tracker'!B27)) -> 0 | L40: =IF(J40<=0,"🎉 DEBT FREE!",IF(K40>=0.75,"75% — keep pushing!",IF(K40>=0.5,"Halfway — momentum!",IF(K40>=0.25,"25% done — great start!","")))) -> 🎉 DEBT FREE!
B41: 33 | C41: =TEXT(EDATE(TODAY(),32),"mmm YYYY") -> Feb 2029 | D41: =IF(J40<=0,0,J40) -> 0 | E41: ='💸 Debt Tracker'!D27 -> 0 | F41: ='💸 Debt Tracker'!G6 -> 0 | G41: =IF(D41<=0,0,MIN(E41+F41,D41)) -> 0 | H41: =IF(D41<=0,0,ROUND(D41*('💸 Debt Tracker'!F27/12),2)) -> 0 | I41: =IF(D41<=0,0,MAX(0,G41-H41)) -> 0 | J41: =IF(D41<=0,0,MAX(0,D41-I41)) -> 0 | K41: =IF('💸 Debt Tracker'!B27=0,0,MAX(0,1-J41/'💸 Debt Tracker'!B27)) -> 0 | L41: =IF(J41<=0,"🎉 DEBT FREE!",IF(K41>=0.75,"75% — keep pushing!",IF(K41>=0.5,"Halfway — momentum!",IF(K41>=0.25,"25% done — great start!","")))) -> 🎉 DEBT FREE!
...

Sheet 🧮 Method Comparison
B1: 🧮 SNOWBALL vs. AVALANCHE — COMPLETE METHOD COMPARISON
B2: Both methods pull live from your 💸 Debt Tracker. See full priority order side-by-side and pick your strategy.
B4: ❄️ SNOWBALL METHOD — Smallest Balance First | H4: 🌋 AVALANCHE METHOD — Highest APR First
B5: DEBT NAME | C5: BALANCE | D5: APR | E5: MIN PMT | F5: PRIORITY | G5: INTEREST | H5: DEBT NAME | I5: BALANCE | J5: APR | K5: MIN PMT | L5: PRIORITY | M5: INTEREST
B6: ='💸 Debt Tracker'!B9 -> e.g. Credit Card 1 | C6: ='💸 Debt Tracker'!C9 -> 0 | D6: ='💸 Debt Tracker'!D9 -> 0 | E6: ='💸 Debt Tracker'!E9 -> 0 | F6: ='💸 Debt Tracker'!I9 -> - | G6: ='💸 Debt Tracker'!G9 -> - | H6: ='💸 Debt Tracker'!B9 -> e.g. Credit Card 1 | I6: ='💸 Debt Tracker'!C9 -> 0 | J6: ='💸 Debt Tracker'!D9 -> 0 | K6: ='💸 Debt Tracker'!E9 -> 0 | L6: ='💸 Debt Tracker'!J9 -> - | M6: ='💸 Debt Tracker'!G9 -> -
B7: ='💸 Debt Tracker'!B10 -> e.g. Car Loan | C7: ='💸 Debt Tracker'!C10 -> 0 | D7: ='💸 Debt Tracker'!D10 -> 0 | E7: ='💸 Debt Tracker'!E10 -> 0 | F7: ='💸 Debt Tracker'!I10 -> - | G7: ='💸 Debt Tracker'!G10 -> - | H7: ='💸 Debt Tracker'!B10 -> e.g. Car Loan | I7: ='💸 Debt Tracker'!C10 -> 0 | J7: ='💸 Debt Tracker'!D10 -> 0 | K7: ='💸 Debt Tracker'!E10 -> 0 | L7: ='💸 Debt Tracker'!J10 -> - | M7: ='💸 Debt Tracker'!G10 -> -
B8: ='💸 Debt Tracker'!B11 -> e.g. Student Loan | C8: ='💸 Debt Tracker'!C11 -> 0 | D8: ='💸 Debt Tracker'!D11 -> 0 | E8: ='💸 Debt Tracker'!E11 -> 0 | F8: ='💸 Debt Tracker'!I11 -> - | G8: ='💸 Debt Tracker'!G11 -> - | H8: ='💸 Debt Tracker'!B11 -> e.g. Student Loan | I8: ='💸 Debt Tracker'!C11 -> 0 | J8: ='💸 Debt Tracker'!D11 -> 0 | K8: ='💸 Debt Tracker'!E11 -> 0 | L8: ='💸 Debt Tracker'!J11 -> - | M8: ='💸 Debt Tracker'!G11 -> -
B9: ='💸 Debt Tracker'!B12 -> e.g. Medical Bill | C9: ='💸 Debt Tracker'!C12 -> 0 | D9: ='💸 Debt Tracker'!D12 -> 0 | E9: ='💸 Debt Tracker'!E12 -> 0 | F9: ='💸 Debt Tracker'!I12 -> - | G9: ='💸 Debt Tracker'!G12 -> - | H9: ='💸 Debt Tracker'!B12 -> e.g. Medical Bill | I9: ='💸 Debt Tracker'!C12 -> 0 | J9: ='💸 Debt Tracker'!D12 -> 0 | K9: ='💸 Debt Tracker'!E12 -> 0 | L9: ='💸 Debt Tracker'!J12 -> - | M9: ='💸 Debt Tracker'!G12 -> -
B10: ='💸 Debt Tracker'!B13 -> e.g. Personal Loan | C10: ='💸 Debt Tracker'!C13 -> 0 | D10: ='💸 Debt Tracker'!D13 -> 0 | E10: ='💸 Debt Tracker'!E13 -> 0 | F10: ='💸 Debt Tracker'!I13 -> - | G10: ='💸 Debt Tracker'!G13 -> - | H10: ='💸 Debt Tracker'!B13 -> e.g. Personal Loan | I10: ='💸 Debt Tracker'!C13 -> 0 | J10: ='💸 Debt Tracker'!D13 -> 0 | K10: ='💸 Debt Tracker'!E13 -> 0 | L10: ='💸 Debt Tracker'!J13 -> - | M10: ='💸 Debt Tracker'!G13 -> -
B11: ='💸 Debt Tracker'!B14 -> 0 | C11: ='💸 Debt Tracker'!C14 -> 0 | D11: ='💸 Debt Tracker'!D14 -> 0 | E11: ='💸 Debt Tracker'!E14 -> 0 | F11: ='💸 Debt Tracker'!I14 -> - | G11: ='💸 Debt Tracker'!G14 -> - | H11: ='💸 Debt Tracker'!B14 -> 0 | I11: ='💸 Debt Tracker'!C14 -> 0 | J11: ='💸 Debt Tracker'!D14 -> 0 | K11: ='💸 Debt Tracker'!E14 -> 0 | L11: ='💸 Debt Tracker'!J14 -> - | M11: ='💸 Debt Tracker'!G14 -> -
B12: ='💸 Debt Tracker'!B15 -> 0 | C12: ='💸 Debt Tracker'!C15 -> 0 | D12: ='💸 Debt Tracker'!D15 -> 0 | E12: ='💸 Debt Tracker'!E15 -> 0 | F12: ='💸 Debt Tracker'!I15 -> - | G12: ='💸 Debt Tracker'!G15 -> - | H12: ='💸 Debt Tracker'!B15 -> 0 | I12: ='💸 Debt Tracker'!C15 -> 0 | J12: ='💸 Debt Tracker'!D15 -> 0 | K12: ='💸 Debt Tracker'!E15 -> 0 | L12: ='💸 Debt Tracker'!J15 -> - | M12: ='💸 Debt Tracker'!G15 -> -
B13: ='💸 Debt Tracker'!B16 -> 0 | C13: ='💸 Debt Tracker'!C16 -> 0 | D13: ='💸 Debt Tracker'!D16 -> 0 | E13: ='💸 Debt Tracker'!E16 -> 0 | F13: ='💸 Debt Tracker'!I16 -> - | G13: ='💸 Debt Tracker'!G16 -> - | H13: ='💸 Debt Tracker'!B16 -> 0 | I13: ='💸 Debt Tracker'!C16 -> 0 | J13: ='💸 Debt Tracker'!D16 -> 0 | K13: ='💸 Debt Tracker'!E16 -> 0 | L13: ='💸 Debt Tracker'!J16 -> - | M13: ='💸 Debt Tracker'!G16 -> -
B14: ='💸 Debt Tracker'!B17 -> 0 | C14: ='💸 Debt Tracker'!C17 -> 0 | D14: ='💸 Debt Tracker'!D17 -> 0 | E14: ='💸 Debt Tracker'!E17 -> 0 | F14: ='💸 Debt Tracker'!I17 -> - | G14: ='💸 Debt Tracker'!G17 -> - | H14: ='💸 Debt Tracker'!B17 -> 0 | I14: ='💸 Debt Tracker'!C17 -> 0 | J14: ='💸 Debt Tracker'!D17 -> 0 | K14: ='💸 Debt Tracker'!E17 -> 0 | L14: ='💸 Debt Tracker'!J17 -> - | M14: ='💸 Debt Tracker'!G17 -> -
B15: ='💸 Debt Tracker'!B18 -> 0 | C15: ='💸 Debt Tracker'!C18 -> 0 | D15: ='💸 Debt Tracker'!D18 -> 0 | E15: ='💸 Debt Tracker'!E18 -> 0 | F15: ='💸 Debt Tracker'!I18 -> - | G15: ='💸 Debt Tracker'!G18 -> - | H15: ='💸 Debt Tracker'!B18 -> 0 | I15: ='💸 Debt Tracker'!C18 -> 0 | J15: ='💸 Debt Tracker'!D18 -> 0 | K15: ='💸 Debt Tracker'!E18 -> 0 | L15: ='💸 Debt Tracker'!J18 -> - | M15: ='💸 Debt Tracker'!G18 -> -
B16: TOTALS | C16: ='💸 Debt Tracker'!C19 -> 0 | E16: ='💸 Debt Tracker'!E19 -> 0 | G16: =SUM(G6:G15) -> 0 | H16: TOTALS | I16: ='💸 Debt Tracker'!C19 -> 0 | K16: ='💸 Debt Tracker'!E19 -> 0 | M16: =SUM(M6:M15) -> 0
B18: 🏆 WHICH METHOD IS RIGHT FOR YOU?
B19: ❄️ SNOWBALL | E19: Best when motivation is your challenge. Pay smallest debt first — quick wins keep you going.
B20: 🌋 AVALANCHE | E20: Best when you want to pay the least interest. Highest APR first is mathematically optimal.
B21: 💡 INTEREST SAVED (Avalanche vs Snowball) | E21: ='💸 Debt Tracker'!D37 -> 0
B23: "Know well the condition of your flocks." — Proverbs 27:23 | AnalyticsByShanikwa.com | Built from real work. Not theory.
